[2025-08-30T22:23:57.389+0000] {taskinstance.py:1159} INFO - Dependencies all met for dep_context=non-requeueable deps ti=<TaskInstance: kaggle_dataset_ingestion.create_directories manual__2025-08-29T00:00:00+00:00 [queued]>
[2025-08-30T22:23:57.396+0000] {taskinstance.py:1159} INFO - Dependencies all met for dep_context=requeueable deps ti=<TaskInstance: kaggle_dataset_ingestion.create_directories manual__2025-08-29T00:00:00+00:00 [queued]>
[2025-08-30T22:23:57.396+0000] {taskinstance.py:1361} INFO - Starting attempt 1 of 3
[2025-08-30T22:23:57.406+0000] {taskinstance.py:1382} INFO - Executing <Task(BashOperator): create_directories> on 2025-08-29 00:00:00+00:00
[2025-08-30T22:23:57.408+0000] {standard_task_runner.py:57} INFO - Started process 75 to run task
[2025-08-30T22:23:57.411+0000] {standard_task_runner.py:84} INFO - Running: ['***', 'tasks', 'run', 'kaggle_dataset_ingestion', 'create_directories', 'manual__2025-08-29T00:00:00+00:00', '--job-id', '9', '--raw', '--subdir', 'DAGS_FOLDER/kaggle_ingestion_dag.py', '--cfg-path', '/tmp/tmpbbeelh61']
[2025-08-30T22:23:57.411+0000] {standard_task_runner.py:85} INFO - Job 9: Subtask create_directories
[2025-08-30T22:23:57.440+0000] {task_command.py:416} INFO - Running <TaskInstance: kaggle_dataset_ingestion.create_directories manual__2025-08-29T00:00:00+00:00 [running]> on host 16db549b6f06
[2025-08-30T22:23:57.491+0000] {taskinstance.py:1662} INFO - Exporting env vars: AIRFLOW_CTX_DAG_OWNER='data-team' AIRFLOW_CTX_DAG_ID='kaggle_dataset_ingestion' AIRFLOW_CTX_TASK_ID='create_directories' AIRFLOW_CTX_EXECUTION_DATE='2025-08-29T00:00:00+00:00' AIRFLOW_CTX_TRY_NUMBER='1' AIRFLOW_CTX_DAG_RUN_ID='manual__2025-08-29T00:00:00+00:00'
[2025-08-30T22:23:57.491+0000] {subprocess.py:63} INFO - Tmp dir root location: /tmp
[2025-08-30T22:23:57.492+0000] {subprocess.py:75} INFO - Running command: ['/bin/bash', '-c', 'mkdir -p /opt/***/data/raw/datasets/titanic && chmod -R 777 /opt/***/data/raw']
[2025-08-30T22:23:57.501+0000] {subprocess.py:86} INFO - Output:
[2025-08-30T22:23:57.503+0000] {subprocess.py:93} INFO - mkdir: cannot create directory ‘/opt/***/data/raw/datasets/titanic’: Permission denied
[2025-08-30T22:23:57.503+0000] {subprocess.py:97} INFO - Command exited with return code 1
[2025-08-30T22:23:57.511+0000] {taskinstance.py:1937} ERROR - Task failed with exception
Traceback (most recent call last):
  File "/home/airflow/.local/lib/python3.8/site-packages/airflow/operators/bash.py", line 210, in execute
    raise AirflowException(
airflow.exceptions.AirflowException: Bash command failed. The command returned a non-zero exit code 1.
[2025-08-30T22:23:57.514+0000] {taskinstance.py:1400} INFO - Marking task as UP_FOR_RETRY. dag_id=kaggle_dataset_ingestion, task_id=create_directories, execution_date=20250829T000000, start_date=20250830T222357, end_date=20250830T222357
[2025-08-30T22:23:57.523+0000] {standard_task_runner.py:104} ERROR - Failed to execute job 9 for task create_directories (Bash command failed. The command returned a non-zero exit code 1.; 75)
[2025-08-30T22:23:57.542+0000] {local_task_job_runner.py:228} INFO - Task exited with return code 1
[2025-08-30T22:23:57.557+0000] {taskinstance.py:2778} INFO - 0 downstream tasks scheduled from follow-on schedule check
[2025-08-30T22:49:39.912+0000] {taskinstance.py:1159} INFO - Dependencies all met for dep_context=non-requeueable deps ti=<TaskInstance: kaggle_dataset_ingestion.create_directories manual__2025-08-29T00:00:00+00:00 [queued]>
[2025-08-30T22:49:39.918+0000] {taskinstance.py:1159} INFO - Dependencies all met for dep_context=requeueable deps ti=<TaskInstance: kaggle_dataset_ingestion.create_directories manual__2025-08-29T00:00:00+00:00 [queued]>
[2025-08-30T22:49:39.919+0000] {taskinstance.py:1361} INFO - Starting attempt 1 of 3
[2025-08-30T22:49:39.931+0000] {taskinstance.py:1382} INFO - Executing <Task(BashOperator): create_directories> on 2025-08-29 00:00:00+00:00
[2025-08-30T22:49:39.936+0000] {standard_task_runner.py:57} INFO - Started process 76 to run task
[2025-08-30T22:49:39.938+0000] {standard_task_runner.py:84} INFO - Running: ['***', 'tasks', 'run', 'kaggle_dataset_ingestion', 'create_directories', 'manual__2025-08-29T00:00:00+00:00', '--job-id', '13', '--raw', '--subdir', 'DAGS_FOLDER/kaggle_ingestion_dag.py', '--cfg-path', '/tmp/tmproitn60o']
[2025-08-30T22:49:39.939+0000] {standard_task_runner.py:85} INFO - Job 13: Subtask create_directories
[2025-08-30T22:49:39.972+0000] {task_command.py:416} INFO - Running <TaskInstance: kaggle_dataset_ingestion.create_directories manual__2025-08-29T00:00:00+00:00 [running]> on host a3d32c343c24
[2025-08-30T22:49:40.031+0000] {taskinstance.py:1662} INFO - Exporting env vars: AIRFLOW_CTX_DAG_OWNER='data-team' AIRFLOW_CTX_DAG_ID='kaggle_dataset_ingestion' AIRFLOW_CTX_TASK_ID='create_directories' AIRFLOW_CTX_EXECUTION_DATE='2025-08-29T00:00:00+00:00' AIRFLOW_CTX_TRY_NUMBER='1' AIRFLOW_CTX_DAG_RUN_ID='manual__2025-08-29T00:00:00+00:00'
[2025-08-30T22:49:40.032+0000] {subprocess.py:63} INFO - Tmp dir root location: /tmp
[2025-08-30T22:49:40.033+0000] {subprocess.py:75} INFO - Running command: ['/bin/bash', '-c', 'mkdir -p /opt/***/data/raw/datasets/titanic && chmod -R 777 /opt/***/data/raw']
[2025-08-30T22:49:40.042+0000] {subprocess.py:86} INFO - Output:
[2025-08-30T22:49:40.044+0000] {subprocess.py:93} INFO - mkdir: cannot create directory ‘/opt/***/data/raw/datasets/titanic’: Permission denied
[2025-08-30T22:49:40.045+0000] {subprocess.py:97} INFO - Command exited with return code 1
[2025-08-30T22:49:40.054+0000] {taskinstance.py:1937} ERROR - Task failed with exception
Traceback (most recent call last):
  File "/home/airflow/.local/lib/python3.8/site-packages/airflow/operators/bash.py", line 210, in execute
    raise AirflowException(
airflow.exceptions.AirflowException: Bash command failed. The command returned a non-zero exit code 1.
[2025-08-30T22:49:40.056+0000] {taskinstance.py:1400} INFO - Marking task as UP_FOR_RETRY. dag_id=kaggle_dataset_ingestion, task_id=create_directories, execution_date=20250829T000000, start_date=20250830T224939, end_date=20250830T224940
[2025-08-30T22:49:40.066+0000] {standard_task_runner.py:104} ERROR - Failed to execute job 13 for task create_directories (Bash command failed. The command returned a non-zero exit code 1.; 76)
[2025-08-30T22:49:40.111+0000] {local_task_job_runner.py:228} INFO - Task exited with return code 1
[2025-08-30T22:49:40.127+0000] {taskinstance.py:2778} INFO - 0 downstream tasks scheduled from follow-on schedule check
