[2025-08-30T22:54:40.386+0000] {taskinstance.py:1159} INFO - Dependencies all met for dep_context=non-requeueable deps ti=<TaskInstance: kaggle_dataset_ingestion.create_directories manual__2025-08-29T00:00:00+00:00 [queued]>
[2025-08-30T22:54:40.391+0000] {taskinstance.py:1159} INFO - Dependencies all met for dep_context=requeueable deps ti=<TaskInstance: kaggle_dataset_ingestion.create_directories manual__2025-08-29T00:00:00+00:00 [queued]>
[2025-08-30T22:54:40.391+0000] {taskinstance.py:1361} INFO - Starting attempt 2 of 3
[2025-08-30T22:54:40.401+0000] {taskinstance.py:1382} INFO - Executing <Task(BashOperator): create_directories> on 2025-08-29 00:00:00+00:00
[2025-08-30T22:54:40.405+0000] {standard_task_runner.py:57} INFO - Started process 162 to run task
[2025-08-30T22:54:40.407+0000] {standard_task_runner.py:84} INFO - Running: ['***', 'tasks', 'run', 'kaggle_dataset_ingestion', 'create_directories', 'manual__2025-08-29T00:00:00+00:00', '--job-id', '15', '--raw', '--subdir', 'DAGS_FOLDER/kaggle_ingestion_dag.py', '--cfg-path', '/tmp/tmpl_fl5uvd']
[2025-08-30T22:54:40.408+0000] {standard_task_runner.py:85} INFO - Job 15: Subtask create_directories
[2025-08-30T22:54:40.439+0000] {task_command.py:416} INFO - Running <TaskInstance: kaggle_dataset_ingestion.create_directories manual__2025-08-29T00:00:00+00:00 [running]> on host a3d32c343c24
[2025-08-30T22:54:40.488+0000] {taskinstance.py:1662} INFO - Exporting env vars: AIRFLOW_CTX_DAG_OWNER='data-team' AIRFLOW_CTX_DAG_ID='kaggle_dataset_ingestion' AIRFLOW_CTX_TASK_ID='create_directories' AIRFLOW_CTX_EXECUTION_DATE='2025-08-29T00:00:00+00:00' AIRFLOW_CTX_TRY_NUMBER='2' AIRFLOW_CTX_DAG_RUN_ID='manual__2025-08-29T00:00:00+00:00'
[2025-08-30T22:54:40.489+0000] {subprocess.py:63} INFO - Tmp dir root location: /tmp
[2025-08-30T22:54:40.490+0000] {subprocess.py:75} INFO - Running command: ['/bin/bash', '-c', 'mkdir -p /opt/***/data/raw/datasets/titanic && chmod -R 777 /opt/***/data/raw']
[2025-08-30T22:54:40.498+0000] {subprocess.py:86} INFO - Output:
[2025-08-30T22:54:40.500+0000] {subprocess.py:93} INFO - mkdir: cannot create directory ‘/opt/***/data/raw/datasets/titanic’: Permission denied
[2025-08-30T22:54:40.500+0000] {subprocess.py:97} INFO - Command exited with return code 1
[2025-08-30T22:54:40.508+0000] {taskinstance.py:1937} ERROR - Task failed with exception
Traceback (most recent call last):
  File "/home/airflow/.local/lib/python3.8/site-packages/airflow/operators/bash.py", line 210, in execute
    raise AirflowException(
airflow.exceptions.AirflowException: Bash command failed. The command returned a non-zero exit code 1.
[2025-08-30T22:54:40.510+0000] {taskinstance.py:1400} INFO - Marking task as UP_FOR_RETRY. dag_id=kaggle_dataset_ingestion, task_id=create_directories, execution_date=20250829T000000, start_date=20250830T225440, end_date=20250830T225440
[2025-08-30T22:54:40.519+0000] {standard_task_runner.py:104} ERROR - Failed to execute job 15 for task create_directories (Bash command failed. The command returned a non-zero exit code 1.; 162)
[2025-08-30T22:54:40.539+0000] {local_task_job_runner.py:228} INFO - Task exited with return code 1
[2025-08-30T22:54:40.555+0000] {taskinstance.py:2778} INFO - 0 downstream tasks scheduled from follow-on schedule check
